2021-06-18 03:42:07,072 INFO    MainThread:3981644 [internal.py:wandb_internal():91] W&B internal server running at pid: 3981644, started at: 2021-06-18 03:42:07.072275
2021-06-18 03:42:07,075 INFO    WriterThread:3981644 [datastore.py:open_for_write():80] open: /home/chengzilong/DDQN/wandb/offline-run-20210618_034206-1gbpj8sq/run-1gbpj8sq.wandb
2021-06-18 03:42:07,076 DEBUG   HandlerThread:3981644 [handler.py:handle_request():124] handle_request: run_start
2021-06-18 03:42:08,181 DEBUG   HandlerThread:3981644 [meta.py:__init__():39] meta init
2021-06-18 03:42:08,181 DEBUG   HandlerThread:3981644 [meta.py:__init__():53] meta init done
2021-06-18 03:42:08,181 DEBUG   HandlerThread:3981644 [meta.py:probe():210] probe
2021-06-18 03:42:08,187 DEBUG   HandlerThread:3981644 [git.py:repo():33] git repository is invalid
2021-06-18 03:42:08,187 DEBUG   HandlerThread:3981644 [meta.py:_save_pip():57] save pip
2021-06-18 03:42:08,188 DEBUG   HandlerThread:3981644 [meta.py:_save_pip():71] save pip done
2021-06-18 03:42:08,188 DEBUG   HandlerThread:3981644 [meta.py:_save_conda():78] save conda
2021-06-18 03:42:12,336 DEBUG   HandlerThread:3981644 [meta.py:_save_conda():86] save conda done
2021-06-18 03:42:12,336 DEBUG   HandlerThread:3981644 [meta.py:probe():252] probe done
2021-06-18 03:42:23,862 WARNING MainThread:3981644 [internal.py:wandb_internal():147] Internal process interrupt: 1
2021-06-18 03:42:24,085 WARNING MainThread:3981644 [internal.py:wandb_internal():147] Internal process interrupt: 2
2021-06-18 03:42:24,085 ERROR   MainThread:3981644 [internal.py:wandb_internal():150] Internal process interrupted.
2021-06-18 03:42:24,868 INFO    WriterThread:3981644 [datastore.py:close():288] close: /home/chengzilong/DDQN/wandb/offline-run-20210618_034206-1gbpj8sq/run-1gbpj8sq.wandb
2021-06-18 03:42:24,870 INFO    HandlerThread:3981644 [handler.py:finish():638] shutting down handler
2021-06-18 03:42:25,084 INFO    SenderThread:3981644 [sender.py:finish():933] shutting down sender
2021-06-18 03:42:25,085 INFO    MainThread:3981644 [internal.py:handle_exit():78] Internal process exited
