2021-06-18 03:43:25,134 INFO    MainThread:3985188 [internal.py:wandb_internal():91] W&B internal server running at pid: 3985188, started at: 2021-06-18 03:43:25.134369
2021-06-18 03:43:25,137 INFO    WriterThread:3985188 [datastore.py:open_for_write():80] open: /home/chengzilong/DDQN/wandb/offline-run-20210618_034324-1v6gxthx/run-1v6gxthx.wandb
2021-06-18 03:43:25,139 DEBUG   HandlerThread:3985188 [handler.py:handle_request():124] handle_request: run_start
2021-06-18 03:43:26,338 DEBUG   HandlerThread:3985188 [meta.py:__init__():39] meta init
2021-06-18 03:43:26,338 DEBUG   HandlerThread:3985188 [meta.py:__init__():53] meta init done
2021-06-18 03:43:26,338 DEBUG   HandlerThread:3985188 [meta.py:probe():210] probe
2021-06-18 03:43:26,344 DEBUG   HandlerThread:3985188 [git.py:repo():33] git repository is invalid
2021-06-18 03:43:26,344 DEBUG   HandlerThread:3985188 [meta.py:_save_pip():57] save pip
2021-06-18 03:43:26,345 DEBUG   HandlerThread:3985188 [meta.py:_save_pip():71] save pip done
2021-06-18 03:43:26,345 DEBUG   HandlerThread:3985188 [meta.py:_save_conda():78] save conda
2021-06-18 03:43:30,317 DEBUG   HandlerThread:3985188 [meta.py:_save_conda():86] save conda done
2021-06-18 03:43:30,318 DEBUG   HandlerThread:3985188 [meta.py:probe():252] probe done
2021-06-18 03:43:39,375 WARNING MainThread:3985188 [internal.py:wandb_internal():147] Internal process interrupt: 1
2021-06-18 03:43:39,550 WARNING MainThread:3985188 [internal.py:wandb_internal():147] Internal process interrupt: 2
2021-06-18 03:43:39,550 ERROR   MainThread:3985188 [internal.py:wandb_internal():150] Internal process interrupted.
2021-06-18 03:43:40,146 INFO    SenderThread:3985188 [sender.py:finish():933] shutting down sender
2021-06-18 03:43:40,382 INFO    WriterThread:3985188 [datastore.py:close():288] close: /home/chengzilong/DDQN/wandb/offline-run-20210618_034324-1v6gxthx/run-1v6gxthx.wandb
2021-06-18 03:43:40,384 INFO    MainThread:3985188 [internal.py:handle_exit():78] Internal process exited
