2021-06-18 03:43:56,449 INFO    MainThread:3986679 [internal.py:wandb_internal():91] W&B internal server running at pid: 3986679, started at: 2021-06-18 03:43:56.449551
2021-06-18 03:43:56,452 INFO    WriterThread:3986679 [datastore.py:open_for_write():80] open: /home/chengzilong/DDQN/wandb/offline-run-20210618_034355-13hb4l6l/run-13hb4l6l.wandb
2021-06-18 03:43:56,453 DEBUG   HandlerThread:3986679 [handler.py:handle_request():124] handle_request: run_start
2021-06-18 03:43:57,656 DEBUG   HandlerThread:3986679 [meta.py:__init__():39] meta init
2021-06-18 03:43:57,656 DEBUG   HandlerThread:3986679 [meta.py:__init__():53] meta init done
2021-06-18 03:43:57,657 DEBUG   HandlerThread:3986679 [meta.py:probe():210] probe
2021-06-18 03:43:57,662 DEBUG   HandlerThread:3986679 [git.py:repo():33] git repository is invalid
2021-06-18 03:43:57,663 DEBUG   HandlerThread:3986679 [meta.py:_save_pip():57] save pip
2021-06-18 03:43:57,663 DEBUG   HandlerThread:3986679 [meta.py:_save_pip():71] save pip done
2021-06-18 03:43:57,664 DEBUG   HandlerThread:3986679 [meta.py:_save_conda():78] save conda
2021-06-18 03:44:01,864 DEBUG   HandlerThread:3986679 [meta.py:_save_conda():86] save conda done
2021-06-18 03:44:01,864 DEBUG   HandlerThread:3986679 [meta.py:probe():252] probe done
2021-06-18 03:44:11,214 WARNING MainThread:3986679 [internal.py:wandb_internal():147] Internal process interrupt: 1
2021-06-18 03:44:11,401 WARNING MainThread:3986679 [internal.py:wandb_internal():147] Internal process interrupt: 2
2021-06-18 03:44:11,402 ERROR   MainThread:3986679 [internal.py:wandb_internal():150] Internal process interrupted.
2021-06-18 03:44:11,463 INFO    SenderThread:3986679 [sender.py:finish():933] shutting down sender
2021-06-18 03:44:12,220 INFO    WriterThread:3986679 [datastore.py:close():288] close: /home/chengzilong/DDQN/wandb/offline-run-20210618_034355-13hb4l6l/run-13hb4l6l.wandb
2021-06-18 03:44:12,222 INFO    MainThread:3986679 [internal.py:handle_exit():78] Internal process exited
