2021-06-18 03:40:06,995 INFO    MainThread:3975741 [internal.py:wandb_internal():91] W&B internal server running at pid: 3975741, started at: 2021-06-18 03:40:06.995626
2021-06-18 03:40:06,998 INFO    WriterThread:3975741 [datastore.py:open_for_write():80] open: /home/chengzilong/DDQN/wandb/offline-run-20210618_034006-q6ofjxfy/run-q6ofjxfy.wandb
2021-06-18 03:40:06,999 DEBUG   HandlerThread:3975741 [handler.py:handle_request():124] handle_request: run_start
2021-06-18 03:40:08,311 DEBUG   HandlerThread:3975741 [meta.py:__init__():39] meta init
2021-06-18 03:40:08,311 DEBUG   HandlerThread:3975741 [meta.py:__init__():53] meta init done
2021-06-18 03:40:08,311 DEBUG   HandlerThread:3975741 [meta.py:probe():210] probe
2021-06-18 03:40:08,317 DEBUG   HandlerThread:3975741 [git.py:repo():33] git repository is invalid
2021-06-18 03:40:08,317 DEBUG   HandlerThread:3975741 [meta.py:_save_pip():57] save pip
2021-06-18 03:40:08,318 DEBUG   HandlerThread:3975741 [meta.py:_save_pip():71] save pip done
2021-06-18 03:40:08,318 DEBUG   HandlerThread:3975741 [meta.py:_save_conda():78] save conda
2021-06-18 03:40:12,528 DEBUG   HandlerThread:3975741 [meta.py:_save_conda():86] save conda done
2021-06-18 03:40:12,528 DEBUG   HandlerThread:3975741 [meta.py:probe():252] probe done
2021-06-18 03:40:25,073 WARNING MainThread:3975741 [internal.py:wandb_internal():147] Internal process interrupt: 1
2021-06-18 03:40:25,363 WARNING MainThread:3975741 [internal.py:wandb_internal():147] Internal process interrupt: 2
2021-06-18 03:40:25,363 ERROR   MainThread:3975741 [internal.py:wandb_internal():150] Internal process interrupted.
2021-06-18 03:40:26,009 INFO    SenderThread:3975741 [sender.py:finish():933] shutting down sender
2021-06-18 03:40:26,079 INFO    WriterThread:3975741 [datastore.py:close():288] close: /home/chengzilong/DDQN/wandb/offline-run-20210618_034006-q6ofjxfy/run-q6ofjxfy.wandb
2021-06-18 03:40:26,081 INFO    MainThread:3975741 [internal.py:handle_exit():78] Internal process exited
