2021-06-18 03:40:11,160 INFO    MainThread:3975998 [internal.py:wandb_internal():91] W&B internal server running at pid: 3975998, started at: 2021-06-18 03:40:11.159992
2021-06-18 03:40:11,162 INFO    WriterThread:3975998 [datastore.py:open_for_write():80] open: /home/chengzilong/DDQN/wandb/offline-run-20210618_034010-1gzuy1gf/run-1gzuy1gf.wandb
2021-06-18 03:40:11,164 DEBUG   HandlerThread:3975998 [handler.py:handle_request():124] handle_request: run_start
2021-06-18 03:40:12,403 DEBUG   HandlerThread:3975998 [meta.py:__init__():39] meta init
2021-06-18 03:40:12,403 DEBUG   HandlerThread:3975998 [meta.py:__init__():53] meta init done
2021-06-18 03:40:12,403 DEBUG   HandlerThread:3975998 [meta.py:probe():210] probe
2021-06-18 03:40:12,409 DEBUG   HandlerThread:3975998 [git.py:repo():33] git repository is invalid
2021-06-18 03:40:12,409 DEBUG   HandlerThread:3975998 [meta.py:_save_pip():57] save pip
2021-06-18 03:40:12,410 DEBUG   HandlerThread:3975998 [meta.py:_save_pip():71] save pip done
2021-06-18 03:40:12,410 DEBUG   HandlerThread:3975998 [meta.py:_save_conda():78] save conda
2021-06-18 03:40:16,369 DEBUG   HandlerThread:3975998 [meta.py:_save_conda():86] save conda done
2021-06-18 03:40:16,370 DEBUG   HandlerThread:3975998 [meta.py:probe():252] probe done
2021-06-18 03:40:38,235 WARNING MainThread:3975998 [internal.py:wandb_internal():147] Internal process interrupt: 1
2021-06-18 03:40:38,476 WARNING MainThread:3975998 [internal.py:wandb_internal():147] Internal process interrupt: 2
2021-06-18 03:40:38,476 ERROR   MainThread:3975998 [internal.py:wandb_internal():150] Internal process interrupted.
2021-06-18 03:40:39,200 INFO    SenderThread:3975998 [sender.py:finish():933] shutting down sender
2021-06-18 03:40:39,240 INFO    WriterThread:3975998 [datastore.py:close():288] close: /home/chengzilong/DDQN/wandb/offline-run-20210618_034010-1gzuy1gf/run-1gzuy1gf.wandb
2021-06-18 03:40:39,241 INFO    HandlerThread:3975998 [handler.py:finish():638] shutting down handler
2021-06-18 03:40:39,243 INFO    MainThread:3975998 [internal.py:handle_exit():78] Internal process exited
