2021-06-18 03:42:01,869 INFO    MainThread:3981239 [internal.py:wandb_internal():91] W&B internal server running at pid: 3981239, started at: 2021-06-18 03:42:01.868957
2021-06-18 03:42:01,871 INFO    WriterThread:3981239 [datastore.py:open_for_write():80] open: /home/chengzilong/DDQN/wandb/offline-run-20210618_034201-1tyjdsig/run-1tyjdsig.wandb
2021-06-18 03:42:01,873 DEBUG   HandlerThread:3981239 [handler.py:handle_request():124] handle_request: run_start
2021-06-18 03:42:03,127 DEBUG   HandlerThread:3981239 [meta.py:__init__():39] meta init
2021-06-18 03:42:03,127 DEBUG   HandlerThread:3981239 [meta.py:__init__():53] meta init done
2021-06-18 03:42:03,127 DEBUG   HandlerThread:3981239 [meta.py:probe():210] probe
2021-06-18 03:42:03,133 DEBUG   HandlerThread:3981239 [git.py:repo():33] git repository is invalid
2021-06-18 03:42:03,133 DEBUG   HandlerThread:3981239 [meta.py:_save_pip():57] save pip
2021-06-18 03:42:03,134 DEBUG   HandlerThread:3981239 [meta.py:_save_pip():71] save pip done
2021-06-18 03:42:03,134 DEBUG   HandlerThread:3981239 [meta.py:_save_conda():78] save conda
2021-06-18 03:42:07,464 DEBUG   HandlerThread:3981239 [meta.py:_save_conda():86] save conda done
2021-06-18 03:42:07,465 DEBUG   HandlerThread:3981239 [meta.py:probe():252] probe done
2021-06-18 03:42:28,028 WARNING MainThread:3981239 [internal.py:wandb_internal():147] Internal process interrupt: 1
2021-06-18 03:42:28,277 WARNING MainThread:3981239 [internal.py:wandb_internal():147] Internal process interrupt: 2
2021-06-18 03:42:28,277 ERROR   MainThread:3981239 [internal.py:wandb_internal():150] Internal process interrupted.
2021-06-18 03:42:28,932 INFO    SenderThread:3981239 [sender.py:finish():933] shutting down sender
2021-06-18 03:42:29,033 INFO    WriterThread:3981239 [datastore.py:close():288] close: /home/chengzilong/DDQN/wandb/offline-run-20210618_034201-1tyjdsig/run-1tyjdsig.wandb
2021-06-18 03:42:29,034 INFO    HandlerThread:3981239 [handler.py:finish():638] shutting down handler
2021-06-18 03:42:29,035 INFO    MainThread:3981239 [internal.py:handle_exit():78] Internal process exited
